YES

The `safeTransferFrom` function and its related parts in the provided Solidity code can throw if any error occurs that is not explicitly checked by the `require` statements within the function. The code includes several points where a revert or throw could happen:

1. If `to` is the zero address, the function will throw due to the `require(to != address(0), "ERC1155: transfer to the zero address");` statement.

2. If the balance of `from` for token `id` is less than `amount`, the function will throw due to the `require(fromBalance >= amount, "ERC1155: insufficient balance for transfer");` statement.

3. If the `from` address is not the caller and is not approved for all by the caller, the function will throw due to the `require(from == _msgSender() || isApprovedForAll(from, _msgSender()), "ERC1155: caller is not token owner or approved");` statement.

4. If the `to` address is a contract and does not correctly implement the `IERC1155Receiver` interface or does not return the expected magic value, the `_doSafeTransferAcceptanceCheck` function will throw.

5. If any other error occurs within the `_beforeTokenTransfer` or `_afterTokenTransfer` hooks that are not caught by the contract, the function will throw.

6. If there is an error in the `try` block within `_doSafeTransferAcceptanceCheck` and it is not one of the expected `catch` cases, the function will throw.

7. If there is an error in any other part of the code that is not handled by a `try-catch` block or a `require` statement, the function will throw.

Since the condition specified is "any other error," and there are multiple points in the code where an unhandled error could cause a throw, the answer is YES, the function can throw if any other error occurs.